DEBUG 2018-03-26 15:23:56,738: 	 Executing command: 'status'
DEBUG 2018-03-26 15:23:56,738: 	 Found CRAB cache file /cms/ldap_home/jhchoi/.crab3
ERROR 2018-03-26 15:23:56,757: 	 Error: crab_crab_ISR_GEN_Ntupler_10to50_v2 is not a valid CRAB project directory.
ERROR 2018-03-26 15:23:56,757: 	 Caught exception
Traceback (most recent call last):
  File "/cvmfs/cms.cern.ch/crab3/slc6_amd64_gcc493/cms/crabclient/3.3.1803/bin/crab", line 160, in <module>
    client()
  File "/cvmfs/cms.cern.ch/crab3/slc6_amd64_gcc493/cms/crabclient/3.3.1803/bin/crab", line 146, in __call__
    self.cmd = sub_cmd(self.logger, args[1:])
  File "/cvmfs/cms.cern.ch/crab3/slc6_amd64_gcc493/cms/crabclient/3.3.1803/lib/python2.7/site-packages/CRABClient/Commands/status.py", line 38, in __init__
    SubCommand.__init__(self, logger, cmdargs)
  File "/cvmfs/cms.cern.ch/crab3/slc6_amd64_gcc493/cms/crabclient/3.3.1803/lib/python2.7/site-packages/CRABClient/Commands/SubCommand.py", line 259, in __init__
    self.validateOptions()
  File "/cvmfs/cms.cern.ch/crab3/slc6_amd64_gcc493/cms/crabclient/3.3.1803/lib/python2.7/site-packages/CRABClient/Commands/status.py", line 972, in validateOptions
    SubCommand.validateOptions(self)
  File "/cvmfs/cms.cern.ch/crab3/slc6_amd64_gcc493/cms/crabclient/3.3.1803/lib/python2.7/site-packages/CRABClient/Commands/SubCommand.py", line 572, in validateOptions
    raise ConfigurationException(msg)
ConfigurationException: [91mError[0m: crab_crab_ISR_GEN_Ntupler_10to50_v2 is not a valid CRAB project directory.
